Workbook
Name IQ_CH: 110000
Name IQ_CQ: 5000
Name IQ_CY: 10000
Name IQ_DAILY: 500000
Name IQ_FH: 100000
Name IQ_FQ: 500
Name IQ_FY: 1000
Name IQ_LTM: 2000
Name IQ_MONTH: 15000
Name IQ_NTM: 6000
Name IQ_WEEK: 50000
Name IQ_YTD: 3000

Sheet Returns_Wide
A1: Simple Returns
A2: Formula: Price_t / Price_(t-1) - 1
A4: Date | B4: =Volume!B4 -> TZTA Comdty | C4: =Volume!C4 -> TZTB Comdty | D4: =Volume!D4 -> TZT1 Comdty | E4: =Volume!#REF! -> #REF! | F4: =Volume!#REF! -> #REF! | G4: =Volume!E4 -> FNA Comdty | H4: =Volume!F4 -> FNB Comdty | I4: =Volume!G4 -> MO1 Comdty | J4: =Volume!H4 -> MO2 Comdty | K4: =Volume!#REF! -> #REF! | L4: =Volume!#REF! -> #REF! | M4: =Volume!#REF! -> #REF! | N4: =Volume!I4 -> XA1 Comdty | O4: =Volume!#REF! -> #REF! | P4: =Volume!#REF! -> #REF! | Q4: =Volume!#REF! -> #REF! | R4: =Volume!#REF! -> #REF! | S4: =Volume!#REF! -> #REF! | T4: =Volume!J4 -> MO1 Comdty | U4: =Volume!K4 -> 0
A5: {=_xll.BDH("AAPL US Equity","PX_LAST",$B$3,$B$4,"Per=D")} -> #N/A Mandatory parameter [STARTDATE] cannot be empty
B6: =IFERROR(Volume!B6/Volume!B5-1,"") | C6: =IFERROR(Volume!C6/Volume!C5-1,"") | D6: =IFERROR(Volume!D6/Volume!D5-1,"") | E6: =IFERROR(Volume!#REF!/Volume!#REF!-1,"") | F6: =IFERROR(Volume!#REF!/Volume!#REF!-1,"") | G6: =IFERROR(Volume!E6/Volume!E5-1,"") | H6: =IFERROR(Volume!F6/Volume!F5-1,"") | I6: =IFERROR(Volume!G6/Volume!G5-1,"") | J6: =IFERROR(Volume!H6/Volume!H5-1,"") | K6: =IFERROR(Volume!#REF!/Volume!#REF!-1,"") | L6: =IFERROR(Volume!#REF!/Volume!#REF!-1,"") | M6: =IFERROR(Volume!#REF!/Volume!#REF!-1,"") | N6: =IFERROR(Volume!I6/Volume!I5-1,"") | O6: =IFERROR(Volume!#REF!/Volume!#REF!-1,"") | P6: =IFERROR(Volume!#REF!/Volume!#REF!-1,"") | Q6: =IFERROR(Volume!#REF!/Volume!#REF!-1,"") | R6: =IFERROR(Volume!#REF!/Volume!#REF!-1,"") | S6: =IFERROR(Volume!#REF!/Volume!#REF!-1,"") | T6: =IFERROR(Volume!J6/Volume!J5-1,"") | U6: =IFERROR(Volume!K6/Volume!K5-1,"")
B7: =IFERROR(Volume!B7/Volume!B6-1,"") | C7: =IFERROR(Volume!C7/Volume!C6-1,"") | D7: =IFERROR(Volume!D7/Volume!D6-1,"") -> 0.41962505 | E7: =IFERROR(Volume!#REF!/Volume!#REF!-1,"") | F7: =IFERROR(Volume!#REF!/Volume!#REF!-1,"") | G7: =IFERROR(Volume!E7/Volume!E6-1,"") | H7: =IFERROR(Volume!F7/Volume!F6-1,"") | I7: =IFERROR(Volume!G7/Volume!G6-1,"") -> -0.51935484 | J7: =IFERROR(Volume!H7/Volume!H6-1,"") | K7: =IFERROR(Volume!#REF!/Volume!#REF!-1,"") | L7: =IFERROR(Volume!#REF!/Volume!#REF!-1,"") | M7: =IFERROR(Volume!#REF!/Volume!#REF!-1,"") | N7: =IFERROR(Volume!I7/Volume!I6-1,"") -> -0.37435897 | O7: =IFERROR(Volume!#REF!/Volume!#REF!-1,"") | P7: =IFERROR(Volume!#REF!/Volume!#REF!-1,"") | Q7: =IFERROR(Volume!#REF!/Volume!#REF!-1,"") | R7: =IFERROR(Volume!#REF!/Volume!#REF!-1,"") | S7: =IFERROR(Volume!#REF!/Volume!#REF!-1,"") | T7: =IFERROR(Volume!J7/Volume!J6-1,"") -> 0.02553542 | U7: =IFERROR(Volume!K7/Volume!K6-1,"")
B8: =IFERROR(Volume!B8/Volume!B7-1,"") | C8: =IFERROR(Volume!C8/Volume!C7-1,"") | D8: =IFERROR(Volume!D8/Volume!D7-1,"") -> -0.43832537 | E8: =IFERROR(Volume!#REF!/Volume!#REF!-1,"") | F8: =IFERROR(Volume!#REF!/Volume!#REF!-1,"") | G8: =IFERROR(Volume!E8/Volume!E7-1,"") | H8: =IFERROR(Volume!F8/Volume!F7-1,"") | I8: =IFERROR(Volume!G8/Volume!G7-1,"") -> -0.28187919 | J8: =IFERROR(Volume!H8/Volume!H7-1,"") | K8: =IFERROR(Volume!#REF!/Volume!#REF!-1,"") | L8: =IFERROR(Volume!#REF!/Volume!#REF!-1,"") | M8: =IFERROR(Volume!#REF!/Volume!#REF!-1,"") | N8: =IFERROR(Volume!I8/Volume!I7-1,"") -> -0.06557377 | O8: =IFERROR(Volume!#REF!/Volume!#REF!-1,"") | P8: =IFERROR(Volume!#REF!/Volume!#REF!-1,"") | Q8: =IFERROR(Volume!#REF!/Volume!#REF!-1,"") | R8: =IFERROR(Volume!#REF!/Volume!#REF!-1,"") | S8: =IFERROR(Volume!#REF!/Volume!#REF!-1,"") | T8: =IFERROR(Volume!J8/Volume!J7-1,"") -> -0.030120482 | U8: =IFERROR(Volume!K8/Volume!K7-1,"")
B9: =IFERROR(Volume!B9/Volume!B8-1,"") | C9: =IFERROR(Volume!C9/Volume!C8-1,"") | D9: =IFERROR(Volume!D9/Volume!D8-1,"") -> 0.26543272 | E9: =IFERROR(Volume!#REF!/Volume!#REF!-1,"") | F9: =IFERROR(Volume!#REF!/Volume!#REF!-1,"") | G9: =IFERROR(Volume!E9/Volume!E8-1,"") | H9: =IFERROR(Volume!F9/Volume!F8-1,"") | I9: =IFERROR(Volume!G9/Volume!G8-1,"") -> 0.29906542 | J9: =IFERROR(Volume!H9/Volume!H8-1,"") | K9: =IFERROR(Volume!#REF!/Volume!#REF!-1,"") | L9: =IFERROR(Volume!#REF!/Volume!#REF!-1,"") | M9: =IFERROR(Volume!#REF!/Volume!#REF!-1,"") | N9: =IFERROR(Volume!I9/Volume!I8-1,"") -> 0.40350877 | O9: =IFERROR(Volume!#REF!/Volume!#REF!-1,"") | P9: =IFERROR(Volume!#REF!/Volume!#REF!-1,"") | Q9: =IFERROR(Volume!#REF!/Volume!#REF!-1,"") | R9: =IFERROR(Volume!#REF!/Volume!#REF!-1,"") | S9: =IFERROR(Volume!#REF!/Volume!#REF!-1,"") | T9: =IFERROR(Volume!J9/Volume!J8-1,"") -> 0.013250518 | U9: =IFERROR(Volume!K9/Volume!K8-1,"")
B10: =IFERROR(Volume!B10/Volume!B9-1,"") | C10: =IFERROR(Volume!C10/Volume!C9-1,"") | D10: =IFERROR(Volume!D10/Volume!D9-1,"") -> -0.080724225 | E10: =IFERROR(Volume!#REF!/Volume!#REF!-1,"") | F10: =IFERROR(Volume!#REF!/Volume!#REF!-1,"") | G10: =IFERROR(Volume!E10/Volume!E9-1,"") | H10: =IFERROR(Volume!F10/Volume!F9-1,"") | I10: =IFERROR(Volume!G10/Volume!G9-1,"") -> 9.6618705 | J10: =IFERROR(Volume!H10/Volume!H9-1,"") | K10: =IFERROR(Volume!#REF!/Volume!#REF!-1,"") | L10: =IFERROR(Volume!#REF!/Volume!#REF!-1,"") | M10: =IFERROR(Volume!#REF!/Volume!#REF!-1,"") | N10: =IFERROR(Volume!I10/Volume!I9-1,"") -> -0.33125 | O10: =IFERROR(Volume!#REF!/Volume!#REF!-1,"") | P10: =IFERROR(Volume!#REF!/Volume!#REF!-1,"") | Q10: =IFERROR(Volume!#REF!/Volume!#REF!-1,"") | R10: =IFERROR(Volume!#REF!/Volume!#REF!-1,"") | S10: =IFERROR(Volume!#REF!/Volume!#REF!-1,"") | T10: =IFERROR(Volume!J10/Volume!J9-1,"") -> -0.020433183 | U10: =IFERROR(Volume!K10/Volume!K9-1,"")
B11: =IFERROR(Volume!B11/Volume!B10-1,"") | C11: =IFERROR(Volume!C11/Volume!C10-1,"") | D11: =IFERROR(Volume!D11/Volume!D10-1,"") -> 0.20762019 | E11: =IFERROR(Volume!#REF!/Volume!#REF!-1,"") | F11: =IFERROR(Volume!#REF!/Volume!#REF!-1,"") | G11: =IFERROR(Volume!E11/Volume!E10-1,"") | H11: =IFERROR(Volume!F11/Volume!F10-1,"") | I11: =IFERROR(Volume!G11/Volume!G10-1,"") -> -0.23684211 | J11: =IFERROR(Volume!H11/Volume!H10-1,"") | K11: =IFERROR(Volume!#REF!/Volume!#REF!-1,"") | L11: =IFERROR(Volume!#REF!/Volume!#REF!-1,"") | M11: =IFERROR(Volume!#REF!/Volume!#REF!-1,"") | N11: =IFERROR(Volume!I11/Volume!I10-1,"") -> 0.90654206 | O11: =IFERROR(Volume!#REF!/Volume!#REF!-1,"") | P11: =IFERROR(Volume!#REF!/Volume!#REF!-1,"") | Q11: =IFERROR(Volume!#REF!/Volume!#REF!-1,"") | R11: =IFERROR(Volume!#REF!/Volume!#REF!-1,"") | S11: =IFERROR(Volume!#REF!/Volume!#REF!-1,"") | T11: =IFERROR(Volume!J11/Volume!J10-1,"") -> 0.025448477 | U11: =IFERROR(Volume!K11/Volume!K10-1,"")
B12: =IFERROR(Volume!B12/Volume!B11-1,"") | C12: =IFERROR(Volume!C12/Volume!C11-1,"") | D12: =IFERROR(Volume!D12/Volume!D11-1,"") -> -0.042091019 | E12: =IFERROR(Volume!#REF!/Volume!#REF!-1,"") | F12: =IFERROR(Volume!#REF!/Volume!#REF!-1,"") | G12: =IFERROR(Volume!E12/Volume!E11-1,"") | H12: =IFERROR(Volume!F12/Volume!F11-1,"") | I12: =IFERROR(Volume!G12/Volume!G11-1,"") -> -0.55791335 | J12: =IFERROR(Volume!H12/Volume!H11-1,"") -> -0.99734043 | K12: =IFERROR(Volume!#REF!/Volume!#REF!-1,"") | L12: =IFERROR(Volume!#REF!/Volume!#REF!-1,"") | M12: =IFERROR(Volume!#REF!/Volume!#REF!-1,"") | N12: =IFERROR(Volume!I12/Volume!I11-1,"") -> -0.28431373 | O12: =IFERROR(Volume!#REF!/Volume!#REF!-1,"") | P12: =IFERROR(Volume!#REF!/Volume!#REF!-1,"") | Q12: =IFERROR(Volume!#REF!/Volume!#REF!-1,"") | R12: =IFERROR(Volume!#REF!/Volume!#REF!-1,"") | S12: =IFERROR(Volume!#REF!/Volume!#REF!-1,"") | T12: =IFERROR(Volume!J12/Volume!J11-1,"") -> -0.018714402 | U12: =IFERROR(Volume!K12/Volume!K11-1,"")
B13: =IFERROR(Volume!B13/Volume!B12-1,"") | C13: =IFERROR(Volume!C13/Volume!C12-1,"") | D13: =IFERROR(Volume!D13/Volume!D12-1,"") -> -0.27591078 | E13: =IFERROR(Volume!#REF!/Volume!#REF!-1,"") | F13: =IFERROR(Volume!#REF!/Volume!#REF!-1,"") | G13: =IFERROR(Volume!E13/Volume!E12-1,"") | H13: =IFERROR(Volume!F13/Volume!F12-1,"") | I13: =IFERROR(Volume!G13/Volume!G12-1,"") -> -0.84 | J13: =IFERROR(Volume!H13/Volume!H12-1,"") | K13: =IFERROR(Volume!#REF!/Volume!#REF!-1,"") | L13: =IFERROR(Volume!#REF!/Volume!#REF!-1,"") | M13: =IFERROR(Volume!#REF!/Volume!#REF!-1,"") | N13: =IFERROR(Volume!I13/Volume!I12-1,"") -> -0.39726027 | O13: =IFERROR(Volume!#REF!/Volume!#REF!-1,"") | P13: =IFERROR(Volume!#REF!/Volume!#REF!-1,"") | Q13: =IFERROR(Volume!#REF!/Volume!#REF!-1,"") | R13: =IFERROR(Volume!#REF!/Volume!#REF!-1,"") | S13: =IFERROR(Volume!#REF!/Volume!#REF!-1,"") | T13: =IFERROR(Volume!J13/Volume!J12-1,"") -> -0.0024875622 | U13: =IFERROR(Volume!K13/Volume!K12-1,"")
B14: =IFERROR(Volume!B14/Volume!B13-1,"") | C14: =IFERROR(Volume!C14/Volume!C13-1,"") | D14: =IFERROR(Volume!D14/Volume!D13-1,"") -> 1.4026081 | E14: =IFERROR(Volume!#REF!/Volume!#REF!-1,"") | F14: =IFERROR(Volume!#REF!/Volume!#REF!-1,"") | G14: =IFERROR(Volume!E14/Volume!E13-1,"") | H14: =IFERROR(Volume!F14/Volume!F13-1,"") | I14: =IFERROR(Volume!G14/Volume!G13-1,"") -> 4.125 | J14: =IFERROR(Volume!H14/Volume!H13-1,"") | K14: =IFERROR(Volume!#REF!/Volume!#REF!-1,"") | L14: =IFERROR(Volume!#REF!/Volume!#REF!-1,"") | M14: =IFERROR(Volume!#REF!/Volume!#REF!-1,"") | N14: =IFERROR(Volume!I14/Volume!I13-1,"") -> 0.82954545 | O14: =IFERROR(Volume!#REF!/Volume!#REF!-1,"") | P14: =IFERROR(Volume!#REF!/Volume!#REF!-1,"") | Q14: =IFERROR(Volume!#REF!/Volume!#REF!-1,"") | R14: =IFERROR(Volume!#REF!/Volume!#REF!-1,"") | S14: =IFERROR(Volume!#REF!/Volume!#REF!-1,"") | T14: =IFERROR(Volume!J14/Volume!J13-1,"") -> -0.0120532 | U14: =IFERROR(Volume!K14/Volume!K13-1,"")
B15: =IFERROR(Volume!B15/Volume!B14-1,"") | C15: =IFERROR(Volume!C15/Volume!C14-1,"") | D15: =IFERROR(Volume!D15/Volume!D14-1,"") -> -0.41215437 | E15: =IFERROR(Volume!#REF!/Volume!#REF!-1,"") | F15: =IFERROR(Volume!#REF!/Volume!#REF!-1,"") | G15: =IFERROR(Volume!E15/Volume!E14-1,"") | H15: =IFERROR(Volume!F15/Volume!F14-1,"") | I15: =IFERROR(Volume!G15/Volume!G14-1,"") -> 0.11707317 | J15: =IFERROR(Volume!H15/Volume!H14-1,"") -> 2.8444444 | K15: =IFERROR(Volume!#REF!/Volume!#REF!-1,"") | L15: =IFERROR(Volume!#REF!/Volume!#REF!-1,"") | M15: =IFERROR(Volume!#REF!/Volume!#REF!-1,"") | N15: =IFERROR(Volume!I15/Volume!I14-1,"") -> -0.64596273 | O15: =IFERROR(Volume!#REF!/Volume!#REF!-1,"") | P15: =IFERROR(Volume!#REF!/Volume!#REF!-1,"") | Q15: =IFERROR(Volume!#REF!/Volume!#REF!-1,"") | R15: =IFERROR(Volume!#REF!/Volume!#REF!-1,"") | S15: =IFERROR(Volume!#REF!/Volume!#REF!-1,"") | T15: =IFERROR(Volume!J15/Volume!J14-1,"") -> 0.027766092 | U15: =IFERROR(Volume!K15/Volume!K14-1,"")
B16: =IFERROR(Volume!B16/Volume!B15-1,"") | C16: =IFERROR(Volume!C16/Volume!C15-1,"") | D16: =IFERROR(Volume!D16/Volume!D15-1,"") -> -0.26354053 | E16: =IFERROR(Volume!#REF!/Volume!#REF!-1,"") | F16: =IFERROR(Volume!#REF!/Volume!#REF!-1,"") | G16: =IFERROR(Volume!E16/Volume!E15-1,"") | H16: =IFERROR(Volume!F16/Volume!F15-1,"") | I16: =IFERROR(Volume!G16/Volume!G15-1,"") -> 2.1135371 | J16: =IFERROR(Volume!H16/Volume!H15-1,"") -> -0.89884393 | K16: =IFERROR(Volume!#REF!/Volume!#REF!-1,"") | L16: =IFERROR(Volume!#REF!/Volume!#REF!-1,"") | M16: =IFERROR(Volume!#REF!/Volume!#REF!-1,"") | N16: =IFERROR(Volume!I16/Volume!I15-1,"") -> 0.035087719 | O16: =IFERROR(Volume!#REF!/Volume!#REF!-1,"") | P16: =IFERROR(Volume!#REF!/Volume!#REF!-1,"") | Q16: =IFERROR(Volume!#REF!/Volume!#REF!-1,"") | R16: =IFERROR(Volume!#REF!/Volume!#REF!-1,"") | S16: =IFERROR(Volume!#REF!/Volume!#REF!-1,"") | T16: =IFERROR(Volume!J16/Volume!J15-1,"") -> 0.013917315 | U16: =IFERROR(Volume!K16/Volume!K15-1,"")
B17: =IFERROR(Volume!B17/Volume!B16-1,"") | C17: =IFERROR(Volume!C17/Volume!C16-1,"") | D17: =IFERROR(Volume!D17/Volume!D16-1,"") -> 0.329615 | E17: =IFERROR(Volume!#REF!/Volume!#REF!-1,"") | F17: =IFERROR(Volume!#REF!/Volume!#REF!-1,"") | G17: =IFERROR(Volume!E17/Volume!E16-1,"") | H17: =IFERROR(Volume!F17/Volume!F16-1,"") | I17: =IFERROR(Volume!G17/Volume!G16-1,"") -> -0.51472651 | J17: =IFERROR(Volume!H17/Volume!H16-1,"") -> 1.8571429 | K17: =IFERROR(Volume!#REF!/Volume!#REF!-1,"") | L17: =IFERROR(Volume!#REF!/Volume!#REF!-1,"") | M17: =IFERROR(Volume!#REF!/Volume!#REF!-1,"") | N17: =IFERROR(Volume!I17/Volume!I16-1,"") -> -0.11864407 | O17: =IFERROR(Volume!#REF!/Volume!#REF!-1,"") | P17: =IFERROR(Volume!#REF!/Volume!#REF!-1,"") | Q17: =IFERROR(Volume!#REF!/Volume!#REF!-1,"") | R17: =IFERROR(Volume!#REF!/Volume!#REF!-1,"") | S17: =IFERROR(Volume!#REF!/Volume!#REF!-1,"") | T17: =IFERROR(Volume!J17/Volume!J16-1,"") -> 0.023819136 | U17: =IFERROR(Volume!K17/Volume!K16-1,"")
... B2505: =IFERROR(Volume!B2505/Volume!B2504-1,"") | C2505: =IFERROR(Volume!C2505/Volume!C2504-1,"") | D2505: =IFERROR(Volume!D2505/Volume!D2504-1,"") | E2505: =IFERROR(Volume!#REF!/Volume!#REF!-1,"") | F2505: =IFERROR(Volume!#REF!/Volume!#REF!-1,"") | G2505: =IFERROR(Volume!E2505/Volume!E2504-1,"") | H2505: =IFERROR(Volume!F2505/Volume!F2504-1,"") | I2505: =IFERROR(Volume!G2505/Volume!G2504-1,"") | J2505: =IFERROR(Volume!H2505/Volume!H2504-1,"") | K2505: =IFERROR(Volume!#REF!/Volume!#REF!-1,"") | L2505: =IFERROR(Volume!#REF!/Volume!#REF!-1,"") | M2505: =IFERROR(Volume!#REF!/Volume!#REF!-1,"") | N2505: =IFERROR(Volume!I2505/Volume!I2504-1,"") | O2505: =IFERROR(Volume!#REF!/Volume!#REF!-1,"") | P2505: =IFERROR(Volume!#REF!/Volume!#REF!-1,"") | Q2505: =IFERROR(Volume!#REF!/Volume!#REF!-1,"") | R2505: =IFERROR(Volume!#REF!/Volume!#REF!-1,"") | S2505: =IFERROR(Volume!#REF!/Volume!#REF!-1,"") | T2505: =IFERROR(Volume!J2505/Volume!J2504-1,"") | U2505: =IFERROR(Volume!K2505/Volume!K2504-1,"")

Sheet Log_Returns_Wide
A1: Log Returns
A2: Formula: LN(Price_t / Price_(t-1))
A4: Date | B4: =Volume!B4 -> TZTA Comdty | C4: =Volume!C4 -> TZTB Comdty | D4: =Volume!D4 -> TZT1 Comdty | E4: =Volume!#REF! -> #REF! | F4: =Volume!#REF! -> #REF! | G4: =Volume!E4 -> FNA Comdty | H4: =Volume!F4 -> FNB Comdty | I4: =Volume!G4 -> MO1 Comdty | J4: =Volume!H4 -> MO2 Comdty | K4: =Volume!#REF! -> #REF! | L4: =Volume!#REF! -> #REF! | M4: =Volume!#REF! -> #REF! | N4: =Volume!I4 -> XA1 Comdty | O4: =Volume!#REF! -> #REF! | P4: =Volume!#REF! -> #REF! | Q4: =Volume!#REF! -> #REF! | R4: =Volume!#REF! -> #REF! | S4: =Volume!#REF! -> #REF! | T4: =Volume!J4 -> MO1 Comdty | U4: =Volume!K4 -> 0
A5: =Volume!A5 -> 43831
A6: =Volume!A6 -> 43832 | B6: =IFERROR(LN(Volume!B6/Volume!B5),"") | C6: =IFERROR(LN(Volume!C6/Volume!C5),"") | D6: =IFERROR(LN(Volume!D6/Volume!D5),"") | E6: =IFERROR(LN(Volume!#REF!/Volume!#REF!),"") | F6: =IFERROR(LN(Volume!#REF!/Volume!#REF!),"") | G6: =IFERROR(LN(Volume!E6/Volume!E5),"") | H6: =IFERROR(LN(Volume!F6/Volume!F5),"") | I6: =IFERROR(LN(Volume!G6/Volume!G5),"") | J6: =IFERROR(LN(Volume!H6/Volume!H5),"") | K6: =IFERROR(LN(Volume!#REF!/Volume!#REF!),"") | L6: =IFERROR(LN(Volume!#REF!/Volume!#REF!),"") | M6: =IFERROR(LN(Volume!#REF!/Volume!#REF!),"") | N6: =IFERROR(LN(Volume!I6/Volume!I5),"") | O6: =IFERROR(LN(Volume!#REF!/Volume!#REF!),"") | P6: =IFERROR(LN(Volume!#REF!/Volume!#REF!),"") | Q6: =IFERROR(LN(Volume!#REF!/Volume!#REF!),"") | R6: =IFERROR(LN(Volume!#REF!/Volume!#REF!),"") | S6: =IFERROR(LN(Volume!#REF!/Volume!#REF!),"") | T6: =IFERROR(LN(Volume!J6/Volume!J5),"") | U6: =IFERROR(LN(Volume!K6/Volume!K5),"")
A7: =Volume!A7 -> 43833 | B7: =IFERROR(LN(Volume!B7/Volume!B6),"") | C7: =IFERROR(LN(Volume!C7/Volume!C6),"") | D7: =IFERROR(LN(Volume!D7/Volume!D6),"") -> 0.35039279 | E7: =IFERROR(LN(Volume!#REF!/Volume!#REF!),"") | F7: =IFERROR(LN(Volume!#REF!/Volume!#REF!),"") | G7: =IFERROR(LN(Volume!E7/Volume!E6),"") | H7: =IFERROR(LN(Volume!F7/Volume!F6),"") | I7: =IFERROR(LN(Volume!G7/Volume!G6),"") -> -0.73262599 | J7: =IFERROR(LN(Volume!H7/Volume!H6),"") | K7: =IFERROR(LN(Volume!#REF!/Volume!#REF!),"") | L7: =IFERROR(LN(Volume!#REF!/Volume!#REF!),"") | M7: =IFERROR(LN(Volume!#REF!/Volume!#REF!),"") | N7: =IFERROR(LN(Volume!I7/Volume!I6),"") -> -0.46897851 | O7: =IFERROR(LN(Volume!#REF!/Volume!#REF!),"") | P7: =IFERROR(LN(Volume!#REF!/Volume!#REF!),"") | Q7: =IFERROR(LN(Volume!#REF!/Volume!#REF!),"") | R7: =IFERROR(LN(Volume!#REF!/Volume!#REF!),"") | S7: =IFERROR(LN(Volume!#REF!/Volume!#REF!),"") | T7: =IFERROR(LN(Volume!J7/Volume!J6),"") -> 0.025214837 | U7: =IFERROR(LN(Volume!K7/Volume!K6),"")
A8: =Volume!A8 -> 43836 | B8: =IFERROR(LN(Volume!B8/Volume!B7),"") | C8: =IFERROR(LN(Volume!C8/Volume!C7),"") | D8: =IFERROR(LN(Volume!D8/Volume!D7),"") -> -0.57683255 | E8: =IFERROR(LN(Volume!#REF!/Volume!#REF!),"") | F8: =IFERROR(LN(Volume!#REF!/Volume!#REF!),"") | G8: =IFERROR(LN(Volume!E8/Volume!E7),"") | H8: =IFERROR(LN(Volume!F8/Volume!F7),"") | I8: =IFERROR(LN(Volume!G8/Volume!G7),"") -> -0.33111747 | J8: =IFERROR(LN(Volume!H8/Volume!H7),"") | K8: =IFERROR(LN(Volume!#REF!/Volume!#REF!),"") | L8: =IFERROR(LN(Volume!#REF!/Volume!#REF!),"") | M8: =IFERROR(LN(Volume!#REF!/Volume!#REF!),"") | N8: =IFERROR(LN(Volume!I8/Volume!I7),"") -> -0.067822596 | O8: =IFERROR(LN(Volume!#REF!/Volume!#REF!),"") | P8: =IFERROR(LN(Volume!#REF!/Volume!#REF!),"") | Q8: =IFERROR(LN(Volume!#REF!/Volume!#REF!),"") | R8: =IFERROR(LN(Volume!#REF!/Volume!#REF!),"") | S8: =IFERROR(LN(Volume!#REF!/Volume!#REF!),"") | T8: =IFERROR(LN(Volume!J8/Volume!J7),"") -> -0.030583423 | U8: =IFERROR(LN(Volume!K8/Volume!K7),"")
A9: =Volume!A9 -> 43837 | B9: =IFERROR(LN(Volume!B9/Volume!B8),"") | C9: =IFERROR(LN(Volume!C9/Volume!C8),"") | D9: =IFERROR(LN(Volume!D9/Volume!D8),"") -> 0.23541413 | E9: =IFERROR(LN(Volume!#REF!/Volume!#REF!),"") | F9: =IFERROR(LN(Volume!#REF!/Volume!#REF!),"") | G9: =IFERROR(LN(Volume!E9/Volume!E8),"") | H9: =IFERROR(LN(Volume!F9/Volume!F8),"") | I9: =IFERROR(LN(Volume!G9/Volume!G8),"") -> 0.2616451 | J9: =IFERROR(LN(Volume!H9/Volume!H8),"") | K9: =IFERROR(LN(Volume!#REF!/Volume!#REF!),"") | L9: =IFERROR(LN(Volume!#REF!/Volume!#REF!),"") | M9: =IFERROR(LN(Volume!#REF!/Volume!#REF!),"") | N9: =IFERROR(LN(Volume!I9/Volume!I8),"") -> 0.33897537 | O9: =IFERROR(LN(Volume!#REF!/Volume!#REF!),"") | P9: =IFERROR(LN(Volume!#REF!/Volume!#REF!),"") | Q9: =IFERROR(LN(Volume!#REF!/Volume!#REF!),"") | R9: =IFERROR(LN(Volume!#REF!/Volume!#REF!),"") | S9: =IFERROR(LN(Volume!#REF!/Volume!#REF!),"") | T9: =IFERROR(LN(Volume!J9/Volume!J8),"") -> 0.013163497 | U9: =IFERROR(LN(Volume!K9/Volume!K8),"")
A10: =Volume!A10 -> 43838 | B10: =IFERROR(LN(Volume!B10/Volume!B9),"") | C10: =IFERROR(LN(Volume!C10/Volume!C9),"") | D10: =IFERROR(LN(Volume!D10/Volume!D9),"") -> -0.08416912 | E10: =IFERROR(LN(Volume!#REF!/Volume!#REF!),"") | F10: =IFERROR(LN(Volume!#REF!/Volume!#REF!),"") | G10: =IFERROR(LN(Volume!E10/Volume!E9),"") | H10: =IFERROR(LN(Volume!F10/Volume!F9),"") | I10: =IFERROR(LN(Volume!G10/Volume!G9),"") -> 2.3666739 | J10: =IFERROR(LN(Volume!H10/Volume!H9),"") | K10: =IFERROR(LN(Volume!#REF!/Volume!#REF!),"") | L10: =IFERROR(LN(Volume!#REF!/Volume!#REF!),"") | M10: =IFERROR(LN(Volume!#REF!/Volume!#REF!),"") | N10: =IFERROR(LN(Volume!I10/Volume!I9),"") -> -0.40234498 | O10: =IFERROR(LN(Volume!#REF!/Volume!#REF!),"") | P10: =IFERROR(LN(Volume!#REF!/Volume!#REF!),"") | Q10: =IFERROR(LN(Volume!#REF!/Volume!#REF!),"") | R10: =IFERROR(LN(Volume!#REF!/Volume!#REF!),"") | S10: =IFERROR(LN(Volume!#REF!/Volume!#REF!),"") | T10: =IFERROR(LN(Volume!J10/Volume!J9),"") -> -0.020644829 | U10: =IFERROR(LN(Volume!K10/Volume!K9),"")
A11: =Volume!A11 -> 43839 | B11: =IFERROR(LN(Volume!B11/Volume!B10),"") | C11: =IFERROR(LN(Volume!C11/Volume!C10),"") | D11: =IFERROR(LN(Volume!D11/Volume!D10),"") -> 0.18865164 | E11: =IFERROR(LN(Volume!#REF!/Volume!#REF!),"") | F11: =IFERROR(LN(Volume!#REF!/Volume!#REF!),"") | G11: =IFERROR(LN(Volume!E11/Volume!E10),"") | H11: =IFERROR(LN(Volume!F11/Volume!F10),"") | I11: =IFERROR(LN(Volume!G11/Volume!G10),"") -> -0.27029033 | J11: =IFERROR(LN(Volume!H11/Volume!H10),"") | K11: =IFERROR(LN(Volume!#REF!/Volume!#REF!),"") | L11: =IFERROR(LN(Volume!#REF!/Volume!#REF!),"") | M11: =IFERROR(LN(Volume!#REF!/Volume!#REF!),"") | N11: =IFERROR(LN(Volume!I11/Volume!I10),"") -> 0.64529116 | O11: =IFERROR(LN(Volume!#REF!/Volume!#REF!),"") | P11: =IFERROR(LN(Volume!#REF!/Volume!#REF!),"") | Q11: =IFERROR(LN(Volume!#REF!/Volume!#REF!),"") | R11: =IFERROR(LN(Volume!#REF!/Volume!#REF!),"") | S11: =IFERROR(LN(Volume!#REF!/Volume!#REF!),"") | T11: =IFERROR(LN(Volume!J11/Volume!J10),"") -> 0.025130056 | U11: =IFERROR(LN(Volume!K11/Volume!K10),"")
A12: =Volume!A12 -> 43840 | B12: =IFERROR(LN(Volume!B12/Volume!B11),"") | C12: =IFERROR(LN(Volume!C12/Volume!C11),"") | D12: =IFERROR(LN(Volume!D12/Volume!D11),"") -> -0.043002515 | E12: =IFERROR(LN(Volume!#REF!/Volume!#REF!),"") | F12: =IFERROR(LN(Volume!#REF!/Volume!#REF!),"") | G12: =IFERROR(LN(Volume!E12/Volume!E11),"") | H12: =IFERROR(LN(Volume!F12/Volume!F11),"") | I12: =IFERROR(LN(Volume!G12/Volume!G11),"") -> -0.81624938 | J12: =IFERROR(LN(Volume!H12/Volume!H11),"") -> -5.9295891 | K12: =IFERROR(LN(Volume!#REF!/Volume!#REF!),"") | L12: =IFERROR(LN(Volume!#REF!/Volume!#REF!),"") | M12: =IFERROR(LN(Volume!#REF!/Volume!#REF!),"") | N12: =IFERROR(LN(Volume!I12/Volume!I11),"") -> -0.33451337 | O12: =IFERROR(LN(Volume!#REF!/Volume!#REF!),"") | P12: =IFERROR(LN(Volume!#REF!/Volume!#REF!),"") | Q12: =IFERROR(LN(Volume!#REF!/Volume!#REF!),"") | R12: =IFERROR(LN(Volume!#REF!/Volume!#REF!),"") | S12: =IFERROR(LN(Volume!#REF!/Volume!#REF!),"") | T12: =IFERROR(LN(Volume!J12/Volume!J11),"") -> -0.018891732 | U12: =IFERROR(LN(Volume!K12/Volume!K11),"")
A13: =Volume!A13 -> 43843 | B13: =IFERROR(LN(Volume!B13/Volume!B12),"") | C13: =IFERROR(LN(Volume!C13/Volume!C12),"") | D13: =IFERROR(LN(Volume!D13/Volume!D12),"") -> -0.32284066 | E13: =IFERROR(LN(Volume!#REF!/Volume!#REF!),"") | F13: =IFERROR(LN(Volume!#REF!/Volume!#REF!),"") | G13: =IFERROR(LN(Volume!E13/Volume!E12),"") | H13: =IFERROR(LN(Volume!F13/Volume!F12),"") | I13: =IFERROR(LN(Volume!G13/Volume!G12),"") -> -1.8325815 | J13: =IFERROR(LN(Volume!H13/Volume!H12),"") | K13: =IFERROR(LN(Volume!#REF!/Volume!#REF!),"") | L13: =IFERROR(LN(Volume!#REF!/Volume!#REF!),"") | M13: =IFERROR(LN(Volume!#REF!/Volume!#REF!),"") | N13: =IFERROR(LN(Volume!I13/Volume!I12),"") -> -0.50626981 | O13: =IFERROR(LN(Volume!#REF!/Volume!#REF!),"") | P13: =IFERROR(LN(Volume!#REF!/Volume!#REF!),"") | Q13: =IFERROR(LN(Volume!#REF!/Volume!#REF!),"") | R13: =IFERROR(LN(Volume!#REF!/Volume!#REF!),"") | S13: =IFERROR(LN(Volume!#REF!/Volume!#REF!),"") | T13: =IFERROR(LN(Volume!J13/Volume!J12),"") -> -0.0024906613 | U13: =IFERROR(LN(Volume!K13/Volume!K12),"")
A14: =Volume!A14 -> 43844 | B14: =IFERROR(LN(Volume!B14/Volume!B13),"") | C14: =IFERROR(LN(Volume!C14/Volume!C13),"") | D14: =IFERROR(LN(Volume!D14/Volume!D13),"") -> 0.87655484 | E14: =IFERROR(LN(Volume!#REF!/Volume!#REF!),"") | F14: =IFERROR(LN(Volume!#REF!/Volume!#REF!),"") | G14: =IFERROR(LN(Volume!E14/Volume!E13),"") | H14: =IFERROR(LN(Volume!F14/Volume!F13),"") | I14: =IFERROR(LN(Volume!G14/Volume!G13),"") -> 1.6341305 | J14: =IFERROR(LN(Volume!H14/Volume!H13),"") | K14: =IFERROR(LN(Volume!#REF!/Volume!#REF!),"") | L14: =IFERROR(LN(Volume!#REF!/Volume!#REF!),"") | M14: =IFERROR(LN(Volume!#REF!/Volume!#REF!),"") | N14: =IFERROR(LN(Volume!I14/Volume!I13),"") -> 0.60406755 | O14: =IFERROR(LN(Volume!#REF!/Volume!#REF!),"") | P14: =IFERROR(LN(Volume!#REF!/Volume!#REF!),"") | Q14: =IFERROR(LN(Volume!#REF!/Volume!#REF!),"") | R14: =IFERROR(LN(Volume!#REF!/Volume!#REF!),"") | S14: =IFERROR(LN(Volume!#REF!/Volume!#REF!),"") | T14: =IFERROR(LN(Volume!J14/Volume!J13),"") -> -0.012126429 | U14: =IFERROR(LN(Volume!K14/Volume!K13),"")
A15: =Volume!A15 -> 43845 | B15: =IFERROR(LN(Volume!B15/Volume!B14),"") | C15: =IFERROR(LN(Volume!C15/Volume!C14),"") | D15: =IFERROR(LN(Volume!D15/Volume!D14),"") -> -0.53129089 | E15: =IFERROR(LN(Volume!#REF!/Volume!#REF!),"") | F15: =IFERROR(LN(Volume!#REF!/Volume!#REF!),"") | G15: =IFERROR(LN(Volume!E15/Volume!E14),"") | H15: =IFERROR(LN(Volume!F15/Volume!F14),"") | I15: =IFERROR(LN(Volume!G15/Volume!G14),"") -> 0.11071202 | J15: =IFERROR(LN(Volume!H15/Volume!H14),"") -> 1.3466291 | K15: =IFERROR(LN(Volume!#REF!/Volume!#REF!),"") | L15: =IFERROR(LN(Volume!#REF!/Volume!#REF!),"") | M15: =IFERROR(LN(Volume!#REF!/Volume!#REF!),"") | N15: =IFERROR(LN(Volume!I15/Volume!I14),"") -> -1.0383531 | O15: =IFERROR(LN(Volume!#REF!/Volume!#REF!),"") | P15: =IFERROR(LN(Volume!#REF!/Volume!#REF!),"") | Q15: =IFERROR(LN(Volume!#REF!/Volume!#REF!),"") | R15: =IFERROR(LN(Volume!#REF!/Volume!#REF!),"") | S15: =IFERROR(LN(Volume!#REF!/Volume!#REF!),"") | T15: =IFERROR(LN(Volume!J15/Volume!J14),"") -> 0.027387604 | U15: =IFERROR(LN(Volume!K15/Volume!K14),"")
A16: =Volume!A16 -> 43846 | B16: =IFERROR(LN(Volume!B16/Volume!B15),"") | C16: =IFERROR(LN(Volume!C16/Volume!C15),"") | D16: =IFERROR(LN(Volume!D16/Volume!D15),"") -> -0.30590108 | E16: =IFERROR(LN(Volume!#REF!/Volume!#REF!),"") | F16: =IFERROR(LN(Volume!#REF!/Volume!#REF!),"") | G16: =IFERROR(LN(Volume!E16/Volume!E15),"") | H16: =IFERROR(LN(Volume!F16/Volume!F15),"") | I16: =IFERROR(LN(Volume!G16/Volume!G15),"") -> 1.1357594 | J16: =IFERROR(LN(Volume!H16/Volume!H15),"") -> -2.2910907 | K16: =IFERROR(LN(Volume!#REF!/Volume!#REF!),"") | L16: =IFERROR(LN(Volume!#REF!/Volume!#REF!),"") | M16: =IFERROR(LN(Volume!#REF!/Volume!#REF!),"") | N16: =IFERROR(LN(Volume!I16/Volume!I15),"") -> 0.034486176 | O16: =IFERROR(LN(Volume!#REF!/Volume!#REF!),"") | P16: =IFERROR(LN(Volume!#REF!/Volume!#REF!),"") | Q16: =IFERROR(LN(Volume!#REF!/Volume!#REF!),"") | R16: =IFERROR(LN(Volume!#REF!/Volume!#REF!),"") | S16: =IFERROR(LN(Volume!#REF!/Volume!#REF!),"") | T16: =IFERROR(LN(Volume!J16/Volume!J15),"") -> 0.013821358 | U16: =IFERROR(LN(Volume!K16/Volume!K15),"")
A17: =Volume!A17 -> 43847 | B17: =IFERROR(LN(Volume!B17/Volume!B16),"") | C17: =IFERROR(LN(Volume!C17/Volume!C16),"") | D17: =IFERROR(LN(Volume!D17/Volume!D16),"") -> 0.28488943 | E17: =IFERROR(LN(Volume!#REF!/Volume!#REF!),"") | F17: =IFERROR(LN(Volume!#REF!/Volume!#REF!),"") | G17: =IFERROR(LN(Volume!E17/Volume!E16),"") | H17: =IFERROR(LN(Volume!F17/Volume!F16),"") | I17: =IFERROR(LN(Volume!G17/Volume!G16),"") -> -0.72304265 | J17: =IFERROR(LN(Volume!H17/Volume!H16),"") -> 1.0498221 | K17: =IFERROR(LN(Volume!#REF!/Volume!#REF!),"") | L17: =IFERROR(LN(Volume!#REF!/Volume!#REF!),"") | M17: =IFERROR(LN(Volume!#REF!/Volume!#REF!),"") | N17: =IFERROR(LN(Volume!I17/Volume!I16),"") -> -0.12629373 | O17: =IFERROR(LN(Volume!#REF!/Volume!#REF!),"") | P17: =IFERROR(LN(Volume!#REF!/Volume!#REF!),"") | Q17: =IFERROR(LN(Volume!#REF!/Volume!#REF!),"") | R17: =IFERROR(LN(Volume!#REF!/Volume!#REF!),"") | S17: =IFERROR(LN(Volume!#REF!/Volume!#REF!),"") | T17: =IFERROR(LN(Volume!J17/Volume!J16),"") -> 0.023539886 | U17: =IFERROR(LN(Volume!K17/Volume!K16),"")
... A2505: =Volume!A2505 -> 0 | B2505: =IFERROR(LN(Volume!B2505/Volume!B2504),"") | C2505: =IFERROR(LN(Volume!C2505/Volume!C2504),"") | D2505: =IFERROR(LN(Volume!D2505/Volume!D2504),"") | E2505: =IFERROR(LN(Volume!#REF!/Volume!#REF!),"") | F2505: =IFERROR(LN(Volume!#REF!/Volume!#REF!),"") | G2505: =IFERROR(LN(Volume!E2505/Volume!E2504),"") | H2505: =IFERROR(LN(Volume!F2505/Volume!F2504),"") | I2505: =IFERROR(LN(Volume!G2505/Volume!G2504),"") | J2505: =IFERROR(LN(Volume!H2505/Volume!H2504),"") | K2505: =IFERROR(LN(Volume!#REF!/Volume!#REF!),"") | L2505: =IFERROR(LN(Volume!#REF!/Volume!#REF!),"") | M2505: =IFERROR(LN(Volume!#REF!/Volume!#REF!),"") | N2505: =IFERROR(LN(Volume!I2505/Volume!I2504),"") | O2505: =IFERROR(LN(Volume!#REF!/Volume!#REF!),"") | P2505: =IFERROR(LN(Volume!#REF!/Volume!#REF!),"") | Q2505: =IFERROR(LN(Volume!#REF!/Volume!#REF!),"") | R2505: =IFERROR(LN(Volume!#REF!/Volume!#REF!),"") | S2505: =IFERROR(LN(Volume!#REF!/Volume!#REF!),"") | T2505: =IFERROR(LN(Volume!J2505/Volume!J2504),"") | U2505: =IFERROR(LN(Volume!K2505/Volume!K2504),"")

Sheet Master List
A1: Ticker | B1: Name / Description | C1: Asset Type | D1: Fields Pulled | E1: Fields Pulled | F1: Fields Pulled | G1: Fields Pulled | H1: Notes
A2: TZTA Comdty | B2: TTF NAT GAS F May26 | C2: Commodity | D2: PX_LAST | E2: PX_VOLUME | F2: OPEN_INT | H2: TTF gas family ticker; exact Bloomberg description still needs confirmation
A3: TZTB Comdty | B3: TTF NAT GAS F Jun26 | C3: Commodity | D3: PX_LAST | E3: PX_VOLUME | F3: OPEN_INT | H3: TTF gas family ticker; exact Bloomberg description still needs confirmation
A4: TZT1 Comdty | B4: Generic 1st 'TZT' Future | C4: Commodity | D4: PX_LAST | E4: PX_VOLUME | F4: OPEN_INT | H4: TTF gas family ticker; exact Bloomberg description still needs confirmation
A5: FNA Comdty | B5: UK Natural Gas FutMay26 | C5: Commodity | D5: PX_LAST | E5: PX_VOLUME | F5: OPEN_INT | H5: Exact Bloomberg description not captured yet
A6: FNB Comdty | B6: UK Natural Gas FutJun26 | C6: Commodity | D6: PX_LAST | E6: PX_VOLUME | F6: OPEN_INT | H6: Exact Bloomberg description not captured yet
A7: MO1 Comdty | B7: Generic 1st 'MO' Future | C7: Commodity | D7: PX_LAST | E7: PX_VOLUME | F7: OPEN_INT | G7: HIST_CALL_IMP_VOL
A8: MO2 Comdty | B8: Generic 2nd 'MO' Future | C8: Commodity | D8: PX_LAST | E8: PX_VOLUME | F8: OPEN_INT | H8: Exact Bloomberg description not captured yet
A9: BDIY Index | B9: BDI Baltic Exchange Dry Index | C9: Index | D9: PX_LAST | H9: Freight / shipping activity proxy
A10: TMR1 Comdty | B10: Generic 1st 'TMR' Future | C10: Commodity | D10: PX_LAST | H10: Alternate TTF month 1 / front-month futures proxy
A11: TTFG1MON Index | B11: NL TTF Nat Gas Month 1 | C11: Index | D11: PX_LAST | H11: TTF forward month 1 benchmark
A12: TTFDDAHD Index | B12: TTF Day-Ahead | C12: Index | D12: PX_LAST | H12: TTF day-ahead spot gas series; history looked short
A13: RTEGNUCT Index | B13: France Gen Nuclear Average | C13: Index | D13: PX_LAST | H13: French nuclear generation proxy
A14: RTEGNUCD Index | B14: France Gen Nuclear Daily | C14: Index | D14: PX_LAST | H14: Alternative French nuclear generation series
A15: API21MON Index | B15: Eur Coal Forward M1 | C15: Index | D15: PX_LAST | H15: European coal forward month 1 benchmark
A16: XA1 Comdty | B16: Generic 1st 'XA' Future | C16: Commodity | D16: PX_LAST | E16: PX_VOLUME | F16: OPEN_INT | H16: Main coal tradable proxy
A17: XAA Comdty | B17: ICE RTD MONTH COA May26 | C17: Commodity | D17: PX_LAST | H17: Alternate Rotterdam coal contract
A18: EEXXT3PA Index | B18: EUA Auction | C18: Index | D18: PX_LAST | H18: Main EUA auction series that worked
A19: ELGB1MON Index | B19: DE Baseload Month 1 | C19: Index | D19: PX_LAST | H19: German baseload month-ahead benchmark
A20: ELGP1MON Index | B20: DE Peakload Month 1 | C20: Index | D20: PX_LAST | H20: German peakload month-ahead benchmark
A21: TZTA Comdty | B21: RK910 | C21: 1M_PUT_IMP_VOL_25DELTA_DFLT | D21: TTF 25D put IV | H21: TTF 25D call IV
A22: TZTA Comdty | B22: RK903 | C22: 1M_CALL_IMP_VOL_25DELTA_DFLT | D22: TTF 25D call IV | H22: TTF 50D put IV
A23: TZTA Comdty | B23: RK908 | C23: 1M_PUT_IMP_VOL_50DELTA_DFLT | D23: TTF 50D put IV | H23: TTF 50D call IV
A24: TZTA Comdty | B24: RK901 | C24: 1M_CALL_IMP_VOL_50DELTA_DFLT | D24: TTF 50D call IV | H24: EUA 25D put IV
A25: MOA Comdty | B25: RK910 | C25: 1M_PUT_IMP_VOL_25DELTA_DFLT | D25: EUA 25D put IV | H25: EUA 25D call IV
A26: MOA Comdty | B26: RK903 | C26: 1M_CALL_IMP_VOL_25DELTA_DFLT | D26: EUA 25D call IV | H26: EUA 50D put IV
A27: MOA Comdty | B27: RK908 | C27: 1M_PUT_IMP_VOL_50DELTA_DFLT | D27: EUA 50D put IV | H27: EUA 50D call IV
A28: MOA Comdty | B28: RK901 | C28: 1M_CALL_IMP_VOL_50DELTA_DFLT | D28: EUA 50D call IV

Sheet Master List COT
A1: MO1 (ICE Brent Crude Oil) — ESMA COT Tickers — All 75 Unique Bloomberg Tickers
A2: ESMA Category | B2: Direction | C2: Group | D2: Field | E2: Bloomberg Ticker | F2: BDP Field (Position) | G2: BDP Field (Chg) | H2: Notes
A3: Investment Firms or Credit Institutions | B3: Long | C3: G1 | D3: Position | E3: IU34DXTZ Index | F3: LAST_PRICE | G3: RT_PX_CHG_NET_1D | H3: -> MM (Money Manager) analog | Futures Only
A4: Investment Firms or Credit Institutions | B4: Long | C4: G1 | D4: PctOI | E4: IU34NIMQ Index | F4: LAST_PRICE | G4: RT_PX_CHG_NET_1D | H4: -> MM (Money Manager) analog | Futures Only
A5: Investment Firms or Credit Institutions | B5: Long | C5: G2 | D5: Position | E5: IU34SOVM Index | F5: LAST_PRICE | G5: RT_PX_CHG_NET_1D | H5: -> MM (Money Manager) analog | Options Only
A6: Investment Firms or Credit Institutions | B6: Long | C6: G2 | D6: PctOI | E6: IU34TKAC Index | F6: LAST_PRICE | G6: RT_PX_CHG_NET_1D | H6: -> MM (Money Manager) analog | Options Only
A7: Investment Firms or Credit Institutions | B7: Long | C7: G3 | D7: Position | E7: IU34LTIS Index | F7: LAST_PRICE | G7: RT_PX_CHG_NET_1D | H7: -> MM (Money Manager) analog | Futures + Options (F+O)
A8: Investment Firms or Credit Institutions | B8: Long | C8: G3 | D8: PctOI | E8: IU34JCIV Index | F8: LAST_PRICE | G8: RT_PX_CHG_NET_1D | H8: -> MM (Money Manager) analog | Futures + Options (F+O)
A9: Investment Firms or Credit Institutions | B9: Short | C9: G1 | D9: Position | E9: IU34XWQO Index | F9: LAST_PRICE | G9: RT_PX_CHG_NET_1D | H9: -> MM (Money Manager) analog | Futures Only
A10: Investment Firms or Credit Institutions | B10: Short | C10: G1 | D10: PctOI | E10: IU34JIHS Index | F10: LAST_PRICE | G10: RT_PX_CHG_NET_1D | H10: -> MM (Money Manager) analog | Futures Only
A11: Investment Firms or Credit Institutions | B11: Short | C11: G2 | D11: Position | E11: IU34PACT Index | F11: LAST_PRICE | G11: RT_PX_CHG_NET_1D | H11: -> MM (Money Manager) analog | Options Only
A12: Investment Firms or Credit Institutions | B12: Short | C12: G2 | D12: PctOI | E12: IU34BDCL Index | F12: LAST_PRICE | G12: RT_PX_CHG_NET_1D | H12: -> MM (Money Manager) analog | Options Only
A13: Investment Firms or Credit Institutions | B13: Short | C13: G3 | D13: Position | E13: IU34YJER Index | F13: LAST_PRICE | G13: RT_PX_CHG_NET_1D | H13: -> MM (Money Manager) analog | Futures + Options (F+O)
... A77: Directive Compliance Obligations | B77: Net | C77: G3 | D77: Position | E77: IU34MHIR Index | F77: LAST_PRICE | G77: RT_PX_CHG_NET_1D | H77: -> NR (Non-Reportable) analog | Futures + Options (F+O)

Sheet Volume
A1: Paste Bloomberg historical price export here
A2: Recommended: export daily PX_LAST in wide format with dates in rows and tickers in columns. Paste starting at A4.
J3: HIST_CALL_IMP_VOL
A4: Date | B4: TZTA Comdty | C4: TZTB Comdty | D4: TZT1 Comdty | E4: FNA Comdty | F4: FNB Comdty | G4: MO1 Comdty | H4: MO2 Comdty | I4: XA1 Comdty | J4: MO1 Comdty
A5: 43831 | B5: #N/A N/A | C5: #N/A N/A | D5: #N/A N/A | E5: #N/A N/A | F5: #N/A N/A | G5: #N/A N/A | H5: #N/A N/A | I5: #N/A N/A | J5: #N/A N/A
A6: =A5+1 -> 43832 | B6: #N/A N/A | C6: #N/A N/A | D6: 12535 | E6: #N/A N/A | F6: #N/A N/A | G6: 310 | H6: #N/A N/A | I6: 195 | J6: 24.28
A7: =WORKDAY(A6,1,0) -> 43833 | B7: #N/A N/A | C7: #N/A N/A | D7: 17795 | E7: #N/A N/A | F7: #N/A N/A | G7: 149 | H7: #N/A N/A | I7: 122 | J7: 24.9
A8: =WORKDAY(A7,1,0) -> 43836 | B8: #N/A N/A | C8: #N/A N/A | D8: 9995 | E8: #N/A N/A | F8: #N/A N/A | G8: 107 | H8: #N/A N/A | I8: 114 | J8: 24.15
A9: =WORKDAY(A8,1,0) -> 43837 | B9: #N/A N/A | C9: #N/A N/A | D9: 12648 | E9: #N/A N/A | F9: #N/A N/A | G9: 139 | H9: #N/A N/A | I9: 160 | J9: 24.47
A10: =WORKDAY(A9,1,0) -> 43838 | B10: #N/A N/A | C10: #N/A N/A | D10: 11627 | E10: #N/A N/A | F10: #N/A N/A | G10: 1482 | H10: #N/A N/A | I10: 107 | J10: 23.97
A11: =WORKDAY(A10,1,0) -> 43839 | B11: #N/A N/A | C11: #N/A N/A | D11: 14041 | E11: #N/A N/A | F11: #N/A N/A | G11: 1131 | H11: 2256 | I11: 204 | J11: 24.58
A12: =WORKDAY(A11,1,0) -> 43840 | B12: #N/A N/A | C12: #N/A N/A | D12: 13450 | E12: #N/A N/A | F12: #N/A N/A | G12: 500 | H12: 6 | I12: 146 | J12: 24.12
A13: =WORKDAY(A12,1,0) -> 43843 | B13: #N/A N/A | C13: #N/A N/A | D13: 9739 | E13: #N/A N/A | F13: #N/A N/A | G13: 80 | H13: #N/A N/A | I13: 88 | J13: 24.06
A14: =WORKDAY(A13,1,0) -> 43844 | B14: #N/A N/A | C14: #N/A N/A | D14: 23399 | E14: #N/A N/A | F14: #N/A N/A | G14: 410 | H14: 90 | I14: 161 | J14: 23.77
A15: =WORKDAY(A14,1,0) -> 43845 | B15: #N/A N/A | C15: #N/A N/A | D15: 13755 | E15: #N/A N/A | F15: #N/A N/A | G15: 458 | H15: 346 | I15: 57 | J15: 24.43
A16: =WORKDAY(A15,1,0) -> 43846 | B16: #N/A N/A | C16: #N/A N/A | D16: 10130 | E16: #N/A N/A | F16: #N/A N/A | G16: 1426 | H16: 35 | I16: 59 | J16: 24.77
A17: =WORKDAY(A16,1,0) -> 43847 | B17: #N/A N/A | C17: #N/A N/A | D17: 13469 | E17: #N/A N/A | F17: #N/A N/A | G17: 692 | H17: 100 | I17: 52 | J17: 25.36
A18: =WORKDAY(A17,1,0) -> 43850 | B18: #N/A N/A | C18: #N/A N/A | D18: 11891 | E18: #N/A N/A | F18: #N/A N/A | G18: 611 | H18: 135 | I18: 40 | J18: 25.11
A19: =WORKDAY(A18,1,0) -> 43851 | B19: #N/A N/A | C19: #N/A N/A | D19: 14946 | E19: #N/A N/A | F19: #N/A N/A | G19: 303 | H19: 121 | I19: 131 | J19: 24.85
A20: =WORKDAY(A19,1,0) -> 43852 | B20: #N/A N/A | C20: #N/A N/A | D20: 13725 | E20: #N/A N/A | F20: #N/A N/A | G20: 70 | H20: #N/A N/A | I20: 21 | J20: 24.94
A21: =WORKDAY(A20,1,0) -> 43853 | B21: #N/A N/A | C21: #N/A N/A | D21: 14900 | E21: #N/A N/A | F21: #N/A N/A | G21: 296 | H21: #N/A N/A | I21: 11 | J21: 24.63
A22: =WORKDAY(A21,1,0) -> 43854 | B22: #N/A N/A | C22: #N/A N/A | D22: 12615 | E22: #N/A N/A | F22: #N/A N/A | G22: 261 | H22: 50 | I22: 1 | J22: 24.3
A23: =WORKDAY(A22,1,0) -> 43857 | B23: #N/A N/A | C23: #N/A N/A | D23: 11043 | E23: #N/A N/A | F23: #N/A N/A | G23: 191 | H23: 15 | I23: 5 | J23: 24.52
A24: =WORKDAY(A23,1,0) -> 43858 | B24: #N/A N/A | C24: #N/A N/A | D24: 18213 | E24: #N/A N/A | F24: #N/A N/A | G24: 113 | H24: 45 | I24: 15 | J24: 24.58
A25: =WORKDAY(A24,1,0) -> 43859 | B25: #N/A N/A | C25: #N/A N/A | D25: 16624 | E25: #N/A N/A | F25: #N/A N/A | G25: 175 | H25: 60 | I25: 8 | J25: 23.92
A26: =WORKDAY(A25,1,0) -> 43860 | B26: #N/A N/A | C26: #N/A N/A | D26: 14092 | E26: #N/A N/A | F26: #N/A N/A | G26: 448 | H26: #N/A N/A | I26: #N/A N/A | J26: 23.67
A27: =WORKDAY(A26,1,0) -> 43861 | B27: #N/A N/A | C27: #N/A N/A | D27: 13710 | E27: #N/A N/A | F27: #N/A N/A | G27: 1062 | H27: #N/A N/A | I27: #N/A N/A | J27: 23.82
A28: =WORKDAY(A27,1,0) -> 43864 | B28: #N/A N/A | C28: #N/A N/A | D28: 10452 | E28: #N/A N/A | F28: #N/A N/A | G28: 326 | H28: #N/A N/A | I28: 57 | J28: 23.15
A29: =WORKDAY(A28,1,0) -> 43865 | B29: #N/A N/A | C29: #N/A N/A | D29: 14438 | E29: #N/A N/A | F29: #N/A N/A | G29: 37 | H29: 41 | I29: 91 | J29: 23.3
A30: =WORKDAY(A29,1,0) -> 43866 | B30: #N/A N/A | C30: #N/A N/A | D30: 15255 | E30: #N/A N/A | F30: #N/A N/A | G30: 100 | H30: 42 | I30: 243 | J30: 23.71
A31: =WORKDAY(A30,1,0) -> 43867 | B31: #N/A N/A | C31: #N/A N/A | D31: 14511 | E31: #N/A N/A | F31: #N/A N/A | G31: 1611 | H31: 35 | I31: 101 | J31: 23.5
A32: =WORKDAY(A31,1,0) -> 43868 | B32: #N/A N/A | C32: #N/A N/A | D32: 14545 | E32: #N/A N/A | F32: #N/A N/A | G32: 132 | H32: 15 | I32: 186 | J32: 23.26
A33: =WORKDAY(A32,1,0) -> 43871 | B33: #N/A N/A | C33: #N/A N/A | D33: 11705 | E33: #N/A N/A | F33: #N/A N/A | G33: 77 | H33: 20 | I33: 28 | J33: 23.11
A34: =WORKDAY(A33,1,0) -> 43872 | B34: #N/A N/A | C34: #N/A N/A | D34: 18146 | E34: #N/A N/A | F34: #N/A N/A | G34: 3044 | H34: 20 | I34: #N/A N/A | J34: 23.25
A35: =WORKDAY(A34,1,0) -> 43873 | B35: #N/A N/A | C35: #N/A N/A | D35: 16915 | E35: #N/A N/A | F35: #N/A N/A | G35: 321 | H35: 20 | I35: 33 | J35: 23.83
A36: =WORKDAY(A35,1,0) -> 43874 | B36: #N/A N/A | C36: #N/A N/A | D36: 15825 | E36: #N/A N/A | F36: #N/A N/A | G36: 232 | H36: 5 | I36: 28 | J36: 24.35
A37: =WORKDAY(A36,1,0) -> 43875 | B37: #N/A N/A | C37: #N/A N/A | D37: 18765 | E37: #N/A N/A | F37: #N/A N/A | G37: 259 | H37: 25 | I37: 11 | J37: 24.24
A38: =WORKDAY(A37,1,0) -> 43878 | B38: #N/A N/A | C38: #N/A N/A | D38: 16425 | E38: #N/A N/A | F38: #N/A N/A | G38: 87 | H38: 15 | I38: 26 | J38: 25
A39: =WORKDAY(A38,1,0) -> 43879 | B39: #N/A N/A | C39: #N/A N/A | D39: 20475 | E39: #N/A N/A | F39: #N/A N/A | G39: 121 | H39: 15 | I39: 1 | J39: 25.09
A40: =WORKDAY(A39,1,0) -> 43880 | B40: #N/A N/A | C40: #N/A N/A | D40: 20205 | E40: #N/A N/A | F40: #N/A N/A | G40: 80 | H40: 316 | I40: #N/A N/A | J40: 25.66
...

Sheet Prices
A1: Paste Bloomberg historical price export here
A2: Recommended: export daily PX_LAST in wide format with dates in rows and tickers in columns. Paste starting at A4.
A4: Date | B4: TZTA Comdty | C4: TZTB Comdty | D4: TZT1 Comdty | E4: FNA Comdty | F4: FNB Comdty | G4: MO1 Comdty | H4: MO2 Comdty | I4: BDIY Index | J4: TMR1 Comdty | K4: TTFG1MON Index | L4: TTFDDAHD Index | M4: RTEGNUCT Index | N4: RTEGNUCD Index | O4: API21MON Index | P4: XA1 Comdty | Q4: XAA Comdty | R4: DEBM A Comdty | S4: DEPK A Comdty | T4: EEXXT3PA Index | U4: ELGB1MON Index | V4: ELGP1MON Index | W4: DBRST3PA Index
A5: 43831 | B5: #N/A N/A | C5: #N/A N/A | D5: #N/A N/A | E5: #N/A N/A | F5: #N/A N/A | G5: #N/A N/A | H5: #N/A N/A | I5: #N/A N/A | J5: #N/A N/A | K5: #N/A N/A | L5: #N/A N/A | M5: 49403 | N5: 1185670 | O5: #N/A N/A | P5: #N/A N/A | Q5: #N/A N/A | R5: #N/A N/A | S5: #N/A N/A | T5: #N/A N/A | U5: #N/A N/A | V5: #N/A N/A | W5: #N/A N/A
A6: =A5+1 -> 43832 | B6: 16.202 | C6: 15.932 | D6: 12.073 | E6: 40.91 | F6: 40.7 | G6: 24.28 | H6: 24.32 | I6: 976 | J6: 3.963 | K6: 12.05 | L6: #N/A N/A | M6: 50085 | N6: 1202051 | O6: #N/A N/A | P6: 52.1 | Q6: #N/A N/A | R6: #N/A N/A | S6: #N/A N/A | T6: #N/A N/A | U6: 39.85 | V6: #N/A N/A | W6: #N/A N/A
A7: =WORKDAY(A6,1,0) -> 43833 | B7: 16.414 | C7: 16.144 | D7: 12.985 | E7: 42.49 | F7: 42.28 | G7: 24.9 | H7: 24.93 | I7: 907 | J7: 4.223 | K7: 12.975 | L7: #N/A N/A | M7: 48881 | N7: 1173136 | O7: #N/A N/A | P7: 52.75 | Q7: #N/A N/A | R7: #N/A N/A | S7: #N/A N/A | T7: #N/A N/A | U7: 40.2 | V7: #N/A N/A | W7: #N/A N/A
A8: =WORKDAY(A7,1,0) -> 43836 | B8: 16.216 | C8: 15.946 | D8: 12.28 | E8: 42.01 | F8: 41.8 | G8: 24.15 | H8: 24.18 | I8: 844 | J8: 4.031 | K8: 12.25 | L8: #N/A N/A | M8: 51770 | N8: 1242490 | O8: #N/A N/A | P8: 52.65 | Q8: #N/A N/A | R8: #N/A N/A | S8: #N/A N/A | T8: #N/A N/A | U8: 39.3 | V8: #N/A N/A | W8: #N/A N/A
A9: =WORKDAY(A8,1,0) -> 43837 | B9: 16.044 | C9: 15.774 | D9: 11.929 | E9: 41.26 | F9: 41.05 | G9: 24.47 | H9: 24.5 | I9: 791 | J9: 3.923 | K9: #N/A N/A | L9: #N/A N/A | M9: 51891 | N9: 1245387 | O9: #N/A N/A | P9: 52.55 | Q9: #N/A N/A | R9: #N/A N/A | S9: #N/A N/A | T9: 24.06 | U9: 38.75 | V9: #N/A N/A | W9: 24.06
A10: =WORKDAY(A9,1,0) -> 43838 | B10: 16.179 | C10: 15.909 | D10: 11.964 | E10: 41.18 | F10: 40.97 | G10: 23.97 | H10: 24.02 | I10: 773 | J10: 3.926 | K10: #N/A N/A | L10: #N/A N/A | M10: 51676 | N10: 1240222 | O10: #N/A N/A | P10: 52.5 | Q10: #N/A N/A | R10: #N/A N/A | S10: #N/A N/A | T10: #N/A N/A | U10: 39 | V10: #N/A N/A | W10: #N/A N/A
A11: =WORKDAY(A10,1,0) -> 43839 | B11: 16.208 | C11: 15.938 | D11: 12.179 | E11: 41.39 | F11: 41.18 | G11: 24.58 | H11: 24.62 | I11: 772 | J11: 3.973 | K11: 12 | L11: #N/A N/A | M11: 45942 | N11: 1102619 | O11: #N/A N/A | P11: 52.7 | Q11: #N/A N/A | R11: #N/A N/A | S11: #N/A N/A | T11: 24.01 | U11: 39.15 | V11: #N/A N/A | W11: 24.01
A12: =WORKDAY(A11,1,0) -> 43840 | B12: 16.21 | C12: 15.94 | D12: 11.94 | E12: 40.98 | F12: 40.77 | G12: 24.12 | H12: 24.16 | I12: 774 | J12: 3.922 | K12: 12 | L12: #N/A N/A | M12: 49475 | N12: 1187409 | O12: #N/A N/A | P12: 52.9 | Q12: #N/A N/A | R12: #N/A N/A | S12: #N/A N/A | T12: 24.48 | U12: 38.65 | V12: #N/A N/A | W12: 24.48
A13: =WORKDAY(A12,1,0) -> 43843 | B13: 16.236 | C13: 15.966 | D13: 12.054 | E13: 41.3 | F13: 41.09 | G13: 24.06 | H13: 24.09 | I13: 765 | J13: 3.951 | K13: #N/A N/A | L13: #N/A N/A | M13: 53695 | N13: 1288687 | O13: 55.15 | P13: 53.5 | Q13: 77.4 | R13: #N/A N/A | S13: #N/A N/A | T13: 24.03 | U13: 38.3 | V13: #N/A N/A | W13: 24.03
A14: =WORKDAY(A13,1,0) -> 43844 | B14: 15.914 | C14: 15.644 | D14: 11.303 | E14: 40.73 | F14: 40.52 | G14: 23.77 | H14: 23.8 | I14: 763 | J14: 3.803 | K14: 11.3 | L14: #N/A N/A | M14: 49302 | N14: 1183242 | O14: 54.6 | P14: 52.2 | Q14: 75.35 | R14: #N/A N/A | S14: #N/A N/A | T14: 23.74 | U14: 36.65 | V14: #N/A N/A | W14: 23.74
A15: =WORKDAY(A14,1,0) -> 43845 | B15: 15.982 | C15: 15.712 | D15: 11.179 | E15: 40.44 | F15: 40.23 | G15: 24.43 | H15: 24.46 | I15: 768 | J15: 3.787 | K15: 11.275 | L15: #N/A N/A | M15: 48965 | N15: 1175155 | O15: #N/A N/A | P15: 51.8 | Q15: 75.4 | R15: #N/A N/A | S15: #N/A N/A | T15: 24.2 | U15: 36.2 | V15: #N/A N/A | W15: 24.2
A16: =WORKDAY(A15,1,0) -> 43846 | B16: 15.981 | C16: 15.711 | D16: 11.117 | E16: 40.01 | F16: 39.8 | G16: 24.77 | H16: 24.8 | I16: 768 | J16: 3.775 | K16: #N/A N/A | L16: #N/A N/A | M16: 49534 | N16: 1188812 | O16: #N/A N/A | P16: 51 | Q16: 74.1 | R16: #N/A N/A | S16: #N/A N/A | T16: 24.85 | U16: 36.05 | V16: #N/A N/A | W16: 24.85
A17: =WORKDAY(A16,1,0) -> 43847 | B17: 15.884 | C17: 15.614 | D17: 10.929 | E17: 39.42 | F17: 39.21 | G17: 25.36 | H17: 25.39 | I17: 754 | J17: 3.74 | K17: #N/A N/A | L17: #N/A N/A | M17: 50039 | N17: 1200946 | O17: #N/A N/A | P17: 50.5 | Q17: 72.2 | R17: #N/A N/A | S17: #N/A N/A | T17: 25.01 | U17: 35.95 | V17: #N/A N/A | W17: 25.01
A18: =WORKDAY(A17,1,0) -> 43850 | B18: 15.972 | C18: 15.857 | D18: 10.566 | E18: 39.36 | F18: 39.15 | G18: 25.11 | H18: 25.14 | I18: 729 | J18: 3.69 | K18: #N/A N/A | L18: #N/A N/A | M18: 49921 | N18: 1198094 | O18: #N/A N/A | P18: 49.75 | Q18: 72.25 | R18: #N/A N/A | S18: #N/A N/A | T18: 25.6 | U18: 34.8 | V18: #N/A N/A | W18: 25.6
A19: =WORKDAY(A18,1,0) -> 43851 | B19: 15.84 | C19: 15.725 | D19: 10.777 | E19: 39.21 | F19: 39 | G19: 24.85 | H19: 24.88 | I19: 689 | J19: 3.717 | K19: #N/A N/A | L19: #N/A N/A | M19: 51360 | N19: 1232646 | O19: #N/A N/A | P19: 50.6 | Q19: 72.8 | R19: #N/A N/A | S19: #N/A N/A | T19: 25.1 | U19: 34.75 | V19: #N/A N/A | W19: 25.1
A20: =WORKDAY(A19,1,0) -> 43852 | B20: 15.77 | C20: 15.655 | D20: 10.455 | E20: 38.35 | F20: 38.14 | G20: 24.94 | H20: 24.97 | I20: 623 | J20: 3.682 | K20: 10.4 | L20: #N/A N/A | M20: 52174 | N20: 1252174 | O20: #N/A N/A | P20: 50.25 | Q20: 72.25 | R20: #N/A N/A | S20: #N/A N/A | T20: #N/A N/A | U20: 35 | V20: #N/A N/A | W20: #N/A N/A
A21: =WORKDAY(A20,1,0) -> 43853 | B21: 15.731 | C21: 15.616 | D21: 10.428 | E21: 38.24 | F21: 38.03 | G21: 24.63 | H21: 24.66 | I21: 576 | J21: 3.677 | K21: #N/A N/A | L21: #N/A N/A | M21: 51311 | N21: 1231466 | O21: #N/A N/A | P21: 50.4 | Q21: 72.95 | R21: #N/A N/A | S21: #N/A N/A | T21: 24.65 | U21: 35.7 | V21: #N/A N/A | W21: 24.65
A22: =WORKDAY(A21,1,0) -> 43854 | B22: 15.365 | C22: 15.25 | D22: 10.455 | E22: 38.09 | F22: 37.88 | G22: 24.3 | H22: 24.33 | I22: 557 | J22: 3.677 | K22: #N/A N/A | L22: #N/A N/A | M22: 50772 | N22: 1218530 | O22: #N/A N/A | P22: 50.25 | Q22: 73.15 | R22: #N/A N/A | S22: #N/A N/A | T22: 24.48 | U22: 35.5 | V22: #N/A N/A | W22: 24.48
A23: =WORKDAY(A22,1,0) -> 43857 | B23: 15.258 | C23: 15.143 | D23: 10.526 | E23: 37.96 | F23: 37.75 | G23: 24.52 | H23: 24.55 | I23: 546 | J23: 3.681 | K23: 10.54 | L23: #N/A N/A | M23: 48536 | N23: 1164870 | O23: #N/A N/A | P23: 50.35 | Q23: 73.2 | R23: #N/A N/A | S23: #N/A N/A | T23: 24.04 | U23: 35.6 | V23: #N/A N/A | W23: 24.04
A24: =WORKDAY(A23,1,0) -> 43858 | B24: 15.64 | C24: 15.525 | D24: 10.792 | E24: 38.39 | F24: 38.18 | G24: 24.58 | H24: 24.61 | I24: 539 | J24: 3.692 | K24: #N/A N/A | L24: #N/A N/A | M24: 49863 | N24: 1196716 | O24: #N/A N/A | P24: 50.35 | Q24: 74.35 | R24: #N/A N/A | S24: #N/A N/A | T24: 24.55 | U24: 35.8 | V24: #N/A N/A | W24: 24.55
A25: =WORKDAY(A24,1,0) -> 43859 | B25: 15.298 | C25: 15.183 | D25: 10.15 | E25: 37.49 | F25: 37.28 | G25: 23.92 | H25: 23.95 | I25: 525 | J25: 3.673 | K25: #N/A N/A | L25: #N/A N/A | M25: 47447 | N25: 1138721 | O25: 49.4 | P25: 50.15 | Q25: 73.85 | R25: #N/A N/A | S25: #N/A N/A | T25: 24.04 | U25: 33.45 | V25: #N/A N/A | W25: 24.04
A26: =WORKDAY(A25,1,0) -> 43860 | B26: 15.04 | C26: 14.925 | D26: 9.781 | E26: 36.31 | F26: 36.1 | G26: 23.67 | H26: 23.7 | I26: 498 | J26: 3.668 | K26: #N/A N/A | L26: #N/A N/A | M26: 49825 | N26: 1195804 | O26: #N/A N/A | P26: 50.45 | Q26: 72 | R26: #N/A N/A | S26: #N/A N/A | T26: 23.74 | U26: 32.1 | V26: #N/A N/A | W26: 23.74
A27: =WORKDAY(A26,1,0) -> 43861 | B27: 14.754 | C27: 14.639 | D27: 9.755 | E27: 36.24 | F27: 36.03 | G27: 23.82 | H27: 23.84 | I27: 487 | J27: 3.168 | K27: 9.775 | L27: #N/A N/A | M27: 48410 | N27: 1161844 | O27: #N/A N/A | P27: 50.35 | Q27: 72.35 | R27: #N/A N/A | S27: #N/A N/A | T27: 23.48 | U27: 31.2 | V27: #N/A N/A | W27: 23.48
A28: =WORKDAY(A27,1,0) -> 43864 | B28: 14.83 | C28: 14.715 | D28: 9.211 | E28: 35.47 | F28: 35.26 | G28: 23.15 | H28: 23.17 | I28: 466 | J28: 2.994 | K28: #N/A N/A | L28: #N/A N/A | M28: 49680 | N28: 1192330 | O28: #N/A N/A | P28: 47.7 | Q28: 72.3 | R28: #N/A N/A | S28: #N/A N/A | T28: 23.2 | U28: 32 | V28: #N/A N/A | W28: 23.2
A29: =WORKDAY(A28,1,0) -> 43865 | B29: 15.171 | C29: 15.056 | D29: 9.366 | E29: 36.28 | F29: 36.07 | G29: 23.3 | H29: 23.32 | I29: 453 | J29: 3.035 | K29: #N/A N/A | L29: #N/A N/A | M29: 51181 | N29: 1228347 | O29: #N/A N/A | P29: 48.9 | Q29: 73.15 | R29: #N/A N/A | S29: #N/A N/A | T29: 23.33 | U29: 32.3 | V29: #N/A N/A | W29: 23.33
A30: =WORKDAY(A29,1,0) -> 43866 | B30: 15.696 | C30: 15.581 | D30: 9.313 | E30: 37.49 | F30: 37.28 | G30: 23.71 | H30: 23.73 | I30: 430 | J30: 3.012 | K30: #N/A N/A | L30: #N/A N/A | M30: 52817 | N30: 1267617 | O30: 51 | P30: 49.45 | Q30: 73.6 | R30: #N/A N/A | S30: #N/A N/A | T30: #N/A N/A | U30: 32.5 | V30: #N/A N/A | W30: #N/A N/A
A31: =WORKDAY(A30,1,0) -> 43867 | B31: 15.464 | C31: 15.349 | D31: 9.149 | E31: 37.18 | F31: 36.97 | G31: 23.5 | H31: 23.52 | I31: 431 | J31: 2.964 | K31: 9.2 | L31: #N/A N/A | M31: 50895 | N31: 1221490 | O31: 49.8 | P31: 48.9 | Q31: 72.7 | R31: #N/A N/A | S31: #N/A N/A | T31: 23.4 | U31: 32.15 | V31: #N/A N/A | W31: 23.4
A32: =WORKDAY(A31,1,0) -> 43868 | B32: 15.6 | C32: 15.485 | D32: 9.068 | E32: 37.7 | F32: 37.49 | G32: 23.26 | H32: 23.28 | I32: 415 | J32: 2.942 | K32: 9.05 | L32: #N/A N/A | M32: 51961 | N32: 1247073 | O32: #N/A N/A | P32: 48.2 | Q32: 71.75 | R32: #N/A N/A | S32: #N/A N/A | T32: 23.17 | U32: 31.2 | V32: #N/A N/A | W32: 23.17
A33: =WORKDAY(A32,1,0) -> 43871 | B33: 15.52 | C33: 15.405 | D33: 8.643 | E33: 36.89 | F33: 36.68 | G33: 23.11 | H33: 23.13 | I33: 411 | J33: 2.839 | K33: #N/A N/A | L33: #N/A N/A | M33: 46869 | N33: 1124854 | O33: #N/A N/A | P33: 47.5 | Q33: 70.75 | R33: #N/A N/A | S33: #N/A N/A | T33: 22.91 | U33: 29.8 | V33: #N/A N/A | W33: 22.91
A34: =WORKDAY(A33,1,0) -> 43872 | B34: 15.964 | C34: 15.849 | D34: 8.557 | E34: 37.09 | F34: 36.88 | G34: 23.25 | H34: 23.27 | I34: 418 | J34: 2.82 | K34: #N/A N/A | L34: 8.85 | M34: 48190 | N34: 1156567 | O34: 49 | P34: 48 | Q34: 71.8 | R34: #N/A N/A | S34: #N/A N/A | T34: 23.15 | U34: 30.2 | V34: #N/A N/A | W34: 23.15
A35: =WORKDAY(A34,1,0) -> 43873 | B35: 16.273 | C35: 16.158 | D35: 8.722 | E35: 37.5 | F35: 37.29 | G35: 23.83 | H35: 23.85 | I35: 421 | J35: 2.848 | K35: #N/A N/A | L35: 9.05 | M35: 49807 | N35: 1195362 | O35: #N/A N/A | P35: 48.75 | Q35: 72.55 | R35: #N/A N/A | S35: #N/A N/A | T35: 23.35 | U35: 30.1 | V35: #N/A N/A | W35: 23.35
A36: =WORKDAY(A35,1,0) -> 43874 | B36: 16.435 | C36: 16.32 | D36: 8.889 | E36: 38.37 | F36: 38.16 | G36: 24.35 | H36: 24.37 | I36: 421 | J36: 2.871 | K36: 8.75 | L36: 8.9 | M36: 48674 | N36: 1168181 | O36: 51.25 | P36: 49.9 | Q36: 73.25 | R36: #N/A N/A | S36: #N/A N/A | T36: 23.52 | U36: 30.45 | V36: #N/A N/A | W36: 23.52
A37: =WORKDAY(A36,1,0) -> 43875 | B37: 16.626 | C37: 16.511 | D37: 8.879 | E37: 38.88 | F37: 38.67 | G37: 24.24 | H37: 24.26 | I37: 425 | J37: 2.869 | K37: #N/A N/A | L37: #N/A N/A | M37: 49831 | N37: 1195951 | O37: #N/A N/A | P37: 50.3 | Q37: 73.45 | R37: #N/A N/A | S37: #N/A N/A | T37: 24.27 | U37: 30.2 | V37: #N/A N/A | W37: 24.27
A38: =WORKDAY(A37,1,0) -> 43878 | B38: 16.576 | C38: 16.461 | D38: 9.312 | E38: 39.53 | F38: 39.32 | G38: 25 | H38: 25.02 | I38: 434 | J38: 2.929 | K38: #N/A N/A | L38: #N/A N/A | M38: 47913 | N38: 1149916 | O38: #N/A N/A | P38: 50.55 | Q38: 74.55 | R38: #N/A N/A | S38: #N/A N/A | T38: 24.11 | U38: 29.6 | V38: #N/A N/A | W38: 24.11
A39: =WORKDAY(A38,1,0) -> 43879 | B39: 16.411 | C39: 16.296 | D39: 9.38 | E39: 39.1 | F39: 38.89 | G39: 25.09 | H39: 25.11 | I39: 450 | J39: 2.937 | K39: #N/A N/A | L39: #N/A N/A | M39: 49930 | N39: 1198309 | O39: #N/A N/A | P39: 49.7 | Q39: 72.75 | R39: #N/A N/A | S39: #N/A N/A | T39: 24.8 | U39: 29.8 | V39: #N/A N/A | W39: 24.8
A40: =WORKDAY(A39,1,0) -> 43880 | B40: 16.139 | C40: 16.024 | D40: 9.572 | E40: 39.28 | F40: 39.07 | G40: 25.66 | H40: 25.68 | I40: 465 | J40: 2.955 | K40: 9.55 | L40: 9.3 | M40: 49174 | N40: 1180175 | O40: #N/A N/A | P40: 49.3 | Q40: 72.45 | R40: #N/A N/A | S40: #N/A N/A | T40: #N/A N/A | U40: 30.25 | V40: #N/A N/A | W40: #N/A N/A
A41: =WORKDAY(A40,1,0) -> 43881 | B41: 15.951 | C41: 15.836 | D41: 9.567 | E41: 38.81 | F41: 38.6 | G41: 25.59 | H41: 25.61 | I41: 480 | J41: 2.956 | K41: #N/A N/A | L41: 9.5 | M41: 45308 | N41: 1087383 | O41: #N/A N/A | P41: 48.4 | Q41: 72.05 | R41: #N/A N/A | S41: #N/A N/A | T41: 25.5 | U41: 30.05 | V41: #N/A N/A | W41: 25.5
...

Sheet Open_Int
A1: Paste Bloomberg historical price export here
A2: Recommended: export daily PX_LAST in wide format with dates in rows and tickers in columns. Paste starting at A4.
A4: Date | B4: TZTA Comdty | C4: TZTB Comdty | D4: TZT1 Comdty | E4: FNA Comdty | F4: FNB Comdty | G4: MO1 Comdty | H4: MO2 Comdty | I4: XA1 Comdty
A5: 43831 | B5: #N/A N/A | C5: #N/A N/A | D5: #N/A N/A | E5: #N/A N/A | F5: #N/A N/A | G5: #N/A N/A | H5: #N/A N/A | I5: #N/A N/A
A6: =A5+1 -> 43832 | B6: #N/A N/A | C6: #N/A N/A | D6: 80628 | E6: #N/A N/A | F6: #N/A N/A | G6: 141224 | H6: 8050 | I6: 3316
A7: =WORKDAY(A6,1,0) -> 43833 | B7: #N/A N/A | C7: #N/A N/A | D7: 80890 | E7: #N/A N/A | F7: #N/A N/A | G7: 141277 | H7: 8050 | I7: 3298
A8: =WORKDAY(A7,1,0) -> 43836 | B8: #N/A N/A | C8: #N/A N/A | D8: 80276 | E8: #N/A N/A | F8: #N/A N/A | G8: 141291 | H8: 8050 | I8: 3257
A9: =WORKDAY(A8,1,0) -> 43837 | B9: #N/A N/A | C9: #N/A N/A | D9: 81858 | E9: #N/A N/A | F9: #N/A N/A | G9: 141345 | H9: 8050 | I9: 3214
A10: =WORKDAY(A9,1,0) -> 43838 | B10: #N/A N/A | C10: #N/A N/A | D10: 81612 | E10: #N/A N/A | F10: #N/A N/A | G10: 142519 | H10: 8050 | I10: 3195
A11: =WORKDAY(A10,1,0) -> 43839 | B11: #N/A N/A | C11: #N/A N/A | D11: 82239 | E11: #N/A N/A | F11: #N/A N/A | G11: 141616 | H11: 8056 | I11: 3121
A12: =WORKDAY(A11,1,0) -> 43840 | B12: #N/A N/A | C12: #N/A N/A | D12: 79135 | E12: #N/A N/A | F12: #N/A N/A | G12: 141122 | H12: 8062 | I12: 3100
A13: =WORKDAY(A12,1,0) -> 43843 | B13: #N/A N/A | C13: #N/A N/A | D13: 78921 | E13: #N/A N/A | F13: #N/A N/A | G13: 141104 | H13: 8062 | I13: 3089
A14: =WORKDAY(A13,1,0) -> 43844 | B14: #N/A N/A | C14: #N/A N/A | D14: 75837 | E14: #N/A N/A | F14: #N/A N/A | G14: 140963 | H14: 8152 | I14: 3060
A15: =WORKDAY(A14,1,0) -> 43845 | B15: #N/A N/A | C15: #N/A N/A | D15: 75610 | E15: #N/A N/A | F15: #N/A N/A | G15: 140627 | H15: 8498 | I15: 3038
A16: =WORKDAY(A15,1,0) -> 43846 | B16: #N/A N/A | C16: #N/A N/A | D16: 74362 | E16: #N/A N/A | F16: #N/A N/A | G16: 140925 | H16: 8533 | I16: 2992
A17: =WORKDAY(A16,1,0) -> 43847 | B17: #N/A N/A | C17: #N/A N/A | D17: 72193 | E17: #N/A N/A | F17: #N/A N/A | G17: 140873 | H17: 8533 | I17: 2955
A18: =WORKDAY(A17,1,0) -> 43850 | B18: #N/A N/A | C18: #N/A N/A | D18: 70515 | E18: #N/A N/A | F18: #N/A N/A | G18: 140826 | H18: 8568 | I18: 2936
... A76: =WORKDAY(A75,1,0) -> 43930 | B76: #N/A N/A | C76: #N/A N/A | D76: 103589 | E76: #N/A N/A | F76: #N/A N/A | G76: 18932 | H76: 4522 | I76: 2429
A77: =WORKDAY(A76,1,0) -> 43931 | B77: #N/A N/A | C77: #N/A N/A | D77: #N/A N/A | E77: #N/A N/A | F77: #N/A N/A | G77: #N/A N/A | H77: #N/A N/A | I77: #N/A N/A
A78: =WORKDAY(A77,1,0) -> 43934 | B78: #N/A N/A | C78: #N/A N/A | D78: 103584 | E78: #N/A N/A | F78: #N/A N/A | G78: 18932 | H78: 4522 | I78: 2429
A79: =WORKDAY(A78,1,0) -> 43935 | B79: #N/A N/A | C79: #N/A N/A | D79: 101636 | E79: #N/A N/A | F79: #N/A N/A | G79: 19186 | H79: 4530 | I79: 2429
A80: =WORKDAY(A79,1,0) -> 43936 | B80: #N/A N/A | C80: #N/A N/A | D80: 100841 | E80: #N/A N/A | F80: #N/A N/A | G80: 20385 | H80: 4555 | I80: 2439
A81: =WORKDAY(A80,1,0) -> 43937 | B81: #N/A N/A | C81: #N/A N/A | D81: 107003 | E81: #N/A N/A | F81: #N/A N/A | G81: 21735 | H81: 4562 | I81: 2439
A82: =WORKDAY(A81,1,0) -> 43938 | B82: #N/A N/A | C82: #N/A N/A | D82: 100961 | E82: #N/A N/A | F82: #N/A N/A | G82: 22684 | H82: 4562 | I82: 2432
A83: =WORKDAY(A82,1,0) -> 43941 | B83: #N/A N/A | C83: #N/A N/A | D83: 95555 | E83: #N/A N/A | F83: #N/A N/A | G83: 23684 | H83: 4562 | I83: 2432
A84: =WORKDAY(A83,1,0) -> 43942 | B84: #N/A N/A | C84: #N/A N/A | D84: 90392 | E84: #N/A N/A | F84: #N/A N/A | G84: 24859 | H84: 4562 | I84: 2432
A85: =WORKDAY(A84,1,0) -> 43943 | B85: #N/A N/A | C85: #N/A N/A | D85: 83795 | E85: #N/A N/A | F85: #N/A N/A | G85: 26122 | H85: 4580 | I85: 2432
A86: =WORKDAY(A85,1,0) -> 43944 | B86: #N/A N/A | C86: #N/A N/A | D86: 84575 | E86: #N/A N/A | F86: #N/A N/A | G86: 26672 | H86: 4586 | I86: 2429
A87: =WORKDAY(A86,1,0) -> 43945 | B87: #N/A N/A | C87: #N/A N/A | D87: 72255 | E87: #N/A N/A | F87: #N/A N/A | G87: 26972 | H87: 4594 | I87: 2454
A88: =WORKDAY(A87,1,0) -> 43948 | B88: #N/A N/A | C88: #N/A N/A | D88: 65594 | E88: #N/A N/A | F88: #N/A N/A | G88: 27422 | H88: 4605 | I88: 2757
A89: =WORKDAY(A88,1,0) -> 43949 | B89: #N/A N/A | C89: #N/A N/A | D89: 59339 | E89: #N/A N/A | F89: #N/A N/A | G89: 28522 | H89: 4614 | I89: 2772
... A237: =WORKDAY(A236,1,0) -> 44155 | B237: #N/A N/A | C237: #N/A N/A | D237: 81113 | E237: #N/A N/A | F237: #N/A N/A | G237: 396767 | H237: 104567 | I237: 2635
A238: =WORKDAY(A237,1,0) -> 44158 | B238: 65 | C238: 65 | D238: 74216 | E238: #N/A N/A | F238: #N/A N/A | G238: 386296 | H238: 106836 | I238: 2638
A239: =WORKDAY(A238,1,0) -> 44159 | B239: 65 | C239: 65 | D239: 73177 | E239: #N/A N/A | F239: #N/A N/A | G239: 385124 | H239: 107236 | I239: 2638
A240: =WORKDAY(A239,1,0) -> 44160 | B240: 75 | C240: 75 | D240: 68887 | E240: #N/A N/A | F240: #N/A N/A | G240: 378349 | H240: 108291 | I240: 2638
A241: =WORKDAY(A240,1,0) -> 44161 | B241: 75 | C241: 75 | D241: 59786 | E241: #N/A N/A | F241: #N/A N/A | G241: 375287 | H241: 109231 | I241: 2638
A242: =WORKDAY(A241,1,0) -> 44162 | B242: 75 | C242: 75 | D242: 49912 | E242: #N/A N/A | F242: #N/A N/A | G242: 368601 | H242: 111267 | I242: 2638
A243: =WORKDAY(A242,1,0) -> 44165 | B243: 75 | C243: 75 | D243: 106656 | E243: #N/A N/A | F243: #N/A N/A | G243: 355405 | H243: 110387 | I243: 3350
A244: =WORKDAY(A243,1,0) -> 44166 | B244: 75 | C244: 75 | D244: 110604 | E244: #N/A N/A | F244: #N/A N/A | G244: 339995 | H244: 109338 | I244: 3368
A245: =WORKDAY(A244,1,0) -> 44167 | B245: 75 | C245: 75 | D245: 108309 | E245: #N/A N/A | F245: #N/A N/A | G245: 334056 | H245: 108551 | I245: 3367
...

Sheet COT
A1: Instrument | C1: EUA
A2: Group | C2: M01 Comdty
A3: Start Date | C3: 43833
A4: End Date | C4: =TODAY() -> 46132
